[2021-06-25 14:25:02,608] {taskinstance.py:876} INFO - Dependencies all met for <TaskInstance: segunda_dag.print_the_context 2021-06-25T14:20:00+00:00 [queued]>
[2021-06-25 14:25:02,622] {taskinstance.py:876} INFO - Dependencies all met for <TaskInstance: segunda_dag.print_the_context 2021-06-25T14:20:00+00:00 [queued]>
[2021-06-25 14:25:02,623] {taskinstance.py:1067} INFO - 
--------------------------------------------------------------------------------
[2021-06-25 14:25:02,624] {taskinstance.py:1068} INFO - Starting attempt 1 of 2
[2021-06-25 14:25:02,625] {taskinstance.py:1069} INFO - 
--------------------------------------------------------------------------------
[2021-06-25 14:25:02,631] {taskinstance.py:1087} INFO - Executing <Task(PythonOperator): print_the_context> on 2021-06-25T14:20:00+00:00
[2021-06-25 14:25:02,638] {standard_task_runner.py:52} INFO - Started process 325 to run task
[2021-06-25 14:25:02,641] {standard_task_runner.py:76} INFO - Running: ['***', 'tasks', 'run', 'segunda_dag', 'print_the_context', '2021-06-25T14:20:00+00:00', '--job-id', '56', '--pool', 'default_pool', '--raw', '--subdir', 'DAGS_FOLDER/segunda_dag.py', '--cfg-path', '/tmp/tmplr3412py', '--error-file', '/tmp/tmppomt78fc']
[2021-06-25 14:25:02,642] {standard_task_runner.py:77} INFO - Job 56: Subtask print_the_context
[2021-06-25 14:25:02,680] {logging_mixin.py:104} INFO - Running <TaskInstance: segunda_dag.print_the_context 2021-06-25T14:20:00+00:00 [running]> on host 72f340316237
[2021-06-25 14:25:02,725] {taskinstance.py:1282} INFO - Exporting the following env vars:
AIRFLOW_CTX_DAG_EMAIL=***@example.com
AIRFLOW_CTX_DAG_OWNER=***
AIRFLOW_CTX_DAG_ID=segunda_dag
AIRFLOW_CTX_TASK_ID=print_the_context
AIRFLOW_CTX_EXECUTION_DATE=2021-06-25T14:20:00+00:00
AIRFLOW_CTX_DAG_RUN_ID=scheduled__2021-06-25T14:20:00+00:00
[2021-06-25 14:25:02,726] {taskinstance.py:1481} ERROR - Task failed with exception
Traceback (most recent call last):
  File "/home/airflow/.local/lib/python3.6/site-packages/airflow/models/taskinstance.py", line 1137, in _run_raw_task
    self._prepare_and_execute_task_with_callbacks(context, task)
  File "/home/airflow/.local/lib/python3.6/site-packages/airflow/models/taskinstance.py", line 1311, in _prepare_and_execute_task_with_callbacks
    result = self._execute_task(context, task_copy)
  File "/home/airflow/.local/lib/python3.6/site-packages/airflow/models/taskinstance.py", line 1341, in _execute_task
    result = task_copy.execute(context=context)
  File "/home/airflow/.local/lib/python3.6/site-packages/airflow/operators/python.py", line 150, in execute
    return_value = self.execute_callable()
  File "/home/airflow/.local/lib/python3.6/site-packages/airflow/operators/python.py", line 161, in execute_callable
    return self.python_callable(*self.op_args, **self.op_kwargs)
TypeError: fazer_alguma_coisa() missing 1 required positional argument: 'p1'
[2021-06-25 14:25:02,730] {taskinstance.py:1531} INFO - Marking task as UP_FOR_RETRY. dag_id=segunda_dag, task_id=print_the_context, execution_date=20210625T142000, start_date=20210625T142502, end_date=20210625T142502
[2021-06-25 14:25:02,773] {local_task_job.py:151} INFO - Task exited with return code 1
